Workbook

Sheet Summary
A1: Referral Service Summary (simulated data)
A2: Simulated data. Targets are assumptions set on the Settings sheet.
A3: Headline measures
A4: Total Referrals | B4: Contacted within target | C4: Overdue: not contacted | D4: Urgent not escalated | E4: Records passing checks
A5: =ROWS(tblReferrals[]) | B5: =COUNTIF(tblReferrals[ContactStatus],"Contacted within target")/(COUNTIF(tblReferrals[ContactStatus],"Contacted within target")+COUNTIF(tblReferrals[ContactStatus],"Contacted late")) | C5: =COUNTIF(tblReferrals[ContactStatus],"Overdue - not contacted") | D5: =COUNTIFS(tblReferrals[PriorityLevel],"Urgent",tblReferrals[Escalated],"No") | E5: =COUNTIF(tblReferrals[QualityFlag],"OK")/ROWS(tblReferrals[])
A6: Targets (assumed) | B6: =Settings!B12 | E6: =Settings!B13
A7: Referrals by month | D7: Referrals by status
A8: Month starting | B8: Referrals | D8: Status | E8: Referrals
A9: 46174 | B9: =COUNTIFS(tblReferrals[DateReceived],">="&A9,tblReferrals[DateReceived],"<"&EDATE(A9,1)) | D9: New | E9: =COUNTIF(tblReferrals[Status],D9)
A10: 46204 | B10: =COUNTIFS(tblReferrals[DateReceived],">="&A10,tblReferrals[DateReceived],"<"&EDATE(A10,1)) | D10: Contacted | E10: =COUNTIF(tblReferrals[Status],D10)
A11: 46235 | B11: =COUNTIFS(tblReferrals[DateReceived],">="&A11,tblReferrals[DateReceived],"<"&EDATE(A11,1)) | D11: Awaiting info | E11: =COUNTIF(tblReferrals[Status],D11)
D12: Consent pending | E12: =COUNTIF(tblReferrals[Status],D12)
D13: Enrolled | E13: =COUNTIF(tblReferrals[Status],D13)
D14: Unable to contact | E14: =COUNTIF(tblReferrals[Status],D14)
D15: Declined | E15: =COUNTIF(tblReferrals[Status],D15)
A23: Time to first contact
A24: Priority | B24: Avg days to first contact
A25: Urgent | B25: =AVERAGEIFS(tblReferrals[DaysToContact],tblReferrals[PriorityLevel],A25,tblReferrals[DaysToContact],">=0")
A26: High | B26: =AVERAGEIFS(tblReferrals[DaysToContact],tblReferrals[PriorityLevel],A26,tblReferrals[DaysToContact],">=0")
A27: Routine | B27: =AVERAGEIFS(tblReferrals[DaysToContact],tblReferrals[PriorityLevel],A27,tblReferrals[DaysToContact],">=0")
A41: Simulated data with small numbers per group: no conclusions should be drawn. With real data, review this view with the team to check that timeliness is equitable.
A43: Key findings
A44: • 65% of contacted referrals were reached within the assumed target times (target 80%); 37 were contacted late.
A45: • 5 referrals are overdue for first contact.
A46: • 4 urgent referrals have no escalation recorded and should be reviewed.
A47: • 27 of 120 records carry a data-quality flag (missing fields, possible duplicates, or inconsistent dates or consent).
A49: Recommended actions
A50: • Contact the 5 overdue referrals and record the outcome.
A51: • Confirm escalation decisions for the 4 urgent referrals.
A52: • Correct the 27 flagged records with referrers, starting with the 5 that have no priority.
A53: • Review whether target times are realistic, since routine referrals average about 6.6 days to first contact.
A55: Based on simulated data and assumed targets.

Sheet Referrals
A1: ReferralID | B1: DateReceived | C1: ClientCode | D1: ReferrerType | E1: Ethnicity | F1: PriorityLevel | G1: InfoComplete | H1: DateFirstContact | I1: ContactMethod | J1: Status | K1: ConsentObtained | L1: AppointmentDate | M1: Escalated | N1: DaysToContact | O1: DaysWaiting | P1: TargetDays | Q1: ContactStatus | R1: QualityFlag
A2: R001 | B2: 46174 | C2: C1007 | D2: GP | E2: Māori | F2: Urgent | G2: Yes | H2: 46174 | I2: In person | J2: Contacted | K2: Pending | M2: Yes | N2: =IF(tblReferrals[[#This Row],[DateFirstContact]]="","",tblReferrals[[#This Row],[DateFirstContact]]-tblReferrals[[#This Row],[DateReceived]]) | O2: =IF(tblReferrals[[#This Row],[DateFirstContact]]="",Settings!$B$3-tblReferrals[[#This Row],[DateReceived]],"") | P2: =IFERROR(INDEX(Settings!$B$6:$B$8,MATCH(tblReferrals[[#This Row],[PriorityLevel]],Settings!$A$6:$A$8,0)),"") | Q2: =IF(tblReferrals[[#This Row],[TargetDays]]="","Check priority",IF(tblReferrals[[#This Row],[DateFirstContact]]="",IF(tblReferrals[[#This Row],[DaysWaiting]]>tblReferrals[[#This Row],[TargetDays]],"Overdue - not contacted","Within target - awaiting contact"),IF(tblReferrals[[#This Row],[DaysToContact]]<0,"Check dates",IF(tblReferrals[[#This Row],[DaysToContact]]<=tblReferrals[[#This Row],[TargetDays]],"Contacted within target","Contacted late")))) | R2: =IF(tblReferrals[[#This Row],[PriorityLevel]]="","Missing priority",IF(tblReferrals[[#This Row],[ReferrerType]]="","Missing referrer type",IF(AND(tblReferrals[[#This Row],[DateFirstContact]]<>"",tblReferrals[[#This Row],[DaysToContact]]<0),"Contact before received",IF(AND(tblReferrals[[#This Row],[Status]]="Enrolled",tblReferrals[[#This Row],[ConsentObtained]]<>"Yes"),"Enrolled without consent",IF(COUNTIF(tblReferrals[ClientCode],tblReferrals[[#This Row],[ClientCode]])>1,"Possible duplicate client",IF(tblReferrals[[#This Row],[Ethnicity]]="","Ethnicity not recorded","OK"))))))
A3: R002 | B3: 46174 | C3: C1014 | D3: GP | E3: Pacific | F3: High | G3: Yes | H3: 46177 | I3: Email | J3: Enrolled | K3: Yes | L3: 46185 | M3: No | N3: =IF(tblReferrals[[#This Row],[DateFirstContact]]="","",tblReferrals[[#This Row],[DateFirstContact]]-tblReferrals[[#This Row],[DateReceived]]) | O3: =IF(tblReferrals[[#This Row],[DateFirstContact]]="",Settings!$B$3-tblReferrals[[#This Row],[DateReceived]],"") | P3: =IFERROR(INDEX(Settings!$B$6:$B$8,MATCH(tblReferrals[[#This Row],[PriorityLevel]],Settings!$A$6:$A$8,0)),"") | Q3: =IF(tblReferrals[[#This Row],[TargetDays]]="","Check priority",IF(tblReferrals[[#This Row],[DateFirstContact]]="",IF(tblReferrals[[#This Row],[DaysWaiting]]>tblReferrals[[#This Row],[TargetDays]],"Overdue - not contacted","Within target - awaiting contact"),IF(tblReferrals[[#This Row],[DaysToContact]]<0,"Check dates",IF(tblReferrals[[#This Row],[DaysToContact]]<=tblReferrals[[#This Row],[TargetDays]],"Contacted within target","Contacted late")))) | R3: =IF(tblReferrals[[#This Row],[PriorityLevel]]="","Missing priority",IF(tblReferrals[[#This Row],[ReferrerType]]="","Missing referrer type",IF(AND(tblReferrals[[#This Row],[DateFirstContact]]<>"",tblReferrals[[#This Row],[DaysToContact]]<0),"Contact before received",IF(AND(tblReferrals[[#This Row],[Status]]="Enrolled",tblReferrals[[#This Row],[ConsentObtained]]<>"Yes"),"Enrolled without consent",IF(COUNTIF(tblReferrals[ClientCode],tblReferrals[[#This Row],[ClientCode]])>1,"Possible duplicate client",IF(tblReferrals[[#This Row],[Ethnicity]]="","Ethnicity not recorded","OK"))))))
A4: R003 | B4: 46175 | C4: C1021 | D4: Hospital | F4: Routine | G4: Yes | H4: 46182 | I4: Phone | J4: Enrolled | K4: Yes | L4: 46192 | M4: No | N4: =IF(tblReferrals[[#This Row],[DateFirstContact]]="","",tblReferrals[[#This Row],[DateFirstContact]]-tblReferrals[[#This Row],[DateReceived]]) | O4: =IF(tblReferrals[[#This Row],[DateFirstContact]]="",Settings!$B$3-tblReferrals[[#This Row],[DateReceived]],"") | P4: =IFERROR(INDEX(Settings!$B$6:$B$8,MATCH(tblReferrals[[#This Row],[PriorityLevel]],Settings!$A$6:$A$8,0)),"") | Q4: =IF(tblReferrals[[#This Row],[TargetDays]]="","Check priority",IF(tblReferrals[[#This Row],[DateFirstContact]]="",IF(tblReferrals[[#This Row],[DaysWaiting]]>tblReferrals[[#This Row],[TargetDays]],"Overdue - not contacted","Within target - awaiting contact"),IF(tblReferrals[[#This Row],[DaysToContact]]<0,"Check dates",IF(tblReferrals[[#This Row],[DaysToContact]]<=tblReferrals[[#This Row],[TargetDays]],"Contacted within target","Contacted late")))) | R4: =IF(tblReferrals[[#This Row],[PriorityLevel]]="","Missing priority",IF(tblReferrals[[#This Row],[ReferrerType]]="","Missing referrer type",IF(AND(tblReferrals[[#This Row],[DateFirstContact]]<>"",tblReferrals[[#This Row],[DaysToContact]]<0),"Contact before received",IF(AND(tblReferrals[[#This Row],[Status]]="Enrolled",tblReferrals[[#This Row],[ConsentObtained]]<>"Yes"),"Enrolled without consent",IF(COUNTIF(tblReferrals[ClientCode],tblReferrals[[#This Row],[ClientCode]])>1,"Possible duplicate client",IF(tblReferrals[[#This Row],[Ethnicity]]="","Ethnicity not recorded","OK"))))))
A5: R004 | B5: 46175 | C5: C1028 | D5: Self-referral | E5: Asian | F5: Routine | G5: Yes | H5: 46184 | I5: Email | J5: Awaiting info | K5: Pending | M5: No | N5: =IF(tblReferrals[[#This Row],[DateFirstContact]]="","",tblReferrals[[#This Row],[DateFirstContact]]-tblReferrals[[#This Row],[DateReceived]]) | O5: =IF(tblReferrals[[#This Row],[DateFirstContact]]="",Settings!$B$3-tblReferrals[[#This Row],[DateReceived]],"") | P5: =IFERROR(INDEX(Settings!$B$6:$B$8,MATCH(tblReferrals[[#This Row],[PriorityLevel]],Settings!$A$6:$A$8,0)),"") | Q5: =IF(tblReferrals[[#This Row],[TargetDays]]="","Check priority",IF(tblReferrals[[#This Row],[DateFirstContact]]="",IF(tblReferrals[[#This Row],[DaysWaiting]]>tblReferrals[[#This Row],[TargetDays]],"Overdue - not contacted","Within target - awaiting contact"),IF(tblReferrals[[#This Row],[DaysToContact]]<0,"Check dates",IF(tblReferrals[[#This Row],[DaysToContact]]<=tblReferrals[[#This Row],[TargetDays]],"Contacted within target","Contacted late")))) | R5: =IF(tblReferrals[[#This Row],[PriorityLevel]]="","Missing priority",IF(tblReferrals[[#This Row],[ReferrerType]]="","Missing referrer type",IF(AND(tblReferrals[[#This Row],[DateFirstContact]]<>"",tblReferrals[[#This Row],[DaysToContact]]<0),"Contact before received",IF(AND(tblReferrals[[#This Row],[Status]]="Enrolled",tblReferrals[[#This Row],[ConsentObtained]]<>"Yes"),"Enrolled without consent",IF(COUNTIF(tblReferrals[ClientCode],tblReferrals[[#This Row],[ClientCode]])>1,"Possible duplicate client",IF(tblReferrals[[#This Row],[Ethnicity]]="","Ethnicity not recorded","OK"))))))
A6: R005 | B6: 46176 | C6: C1035 | D6: Midwife | E6: Asian | F6: Routine | G6: Yes | H6: 46185 | I6: Text | J6: Enrolled | K6: Yes | L6: 46198 | M6: No | N6: =IF(tblReferrals[[#This Row],[DateFirstContact]]="","",tblReferrals[[#This Row],[DateFirstContact]]-tblReferrals[[#This Row],[DateReceived]]) | O6: =IF(tblReferrals[[#This Row],[DateFirstContact]]="",Settings!$B$3-tblReferrals[[#This Row],[DateReceived]],"") | P6: =IFERROR(INDEX(Settings!$B$6:$B$8,MATCH(tblReferrals[[#This Row],[PriorityLevel]],Settings!$A$6:$A$8,0)),"") | Q6: =IF(tblReferrals[[#This Row],[TargetDays]]="","Check priority",IF(tblReferrals[[#This Row],[DateFirstContact]]="",IF(tblReferrals[[#This Row],[DaysWaiting]]>tblReferrals[[#This Row],[TargetDays]],"Overdue - not contacted","Within target - awaiting contact"),IF(tblReferrals[[#This Row],[DaysToContact]]<0,"Check dates",IF(tblReferrals[[#This Row],[DaysToContact]]<=tblReferrals[[#This Row],[TargetDays]],"Contacted within target","Contacted late")))) | R6: =IF(tblReferrals[[#This Row],[PriorityLevel]]="","Missing priority",IF(tblReferrals[[#This Row],[ReferrerType]]="","Missing referrer type",IF(AND(tblReferrals[[#This Row],[DateFirstContact]]<>"",tblReferrals[[#This Row],[DaysToContact]]<0),"Contact before received",IF(AND(tblReferrals[[#This Row],[Status]]="Enrolled",tblReferrals[[#This Row],[ConsentObtained]]<>"Yes"),"Enrolled without consent",IF(COUNTIF(tblReferrals[ClientCode],tblReferrals[[#This Row],[ClientCode]])>1,"Possible duplicate client",IF(tblReferrals[[#This Row],[Ethnicity]]="","Ethnicity not recorded","OK"))))))
A7: R006 | B7: 46177 | C7: C1042 | D7: Other health provider | E7: Pacific | F7: Routine | G7: Yes | H7: 46178 | I7: Phone | J7: Declined | K7: No | M7: No | N7: =IF(tblReferrals[[#This Row],[DateFirstContact]]="","",tblReferrals[[#This Row],[DateFirstContact]]-tblReferrals[[#This Row],[DateReceived]]) | O7: =IF(tblReferrals[[#This Row],[DateFirstContact]]="",Settings!$B$3-tblReferrals[[#This Row],[DateReceived]],"") | P7: =IFERROR(INDEX(Settings!$B$6:$B$8,MATCH(tblReferrals[[#This Row],[PriorityLevel]],Settings!$A$6:$A$8,0)),"") | Q7: =IF(tblReferrals[[#This Row],[TargetDays]]="","Check priority",IF(tblReferrals[[#This Row],[DateFirstContact]]="",IF(tblReferrals[[#This Row],[DaysWaiting]]>tblReferrals[[#This Row],[TargetDays]],"Overdue - not contacted","Within target - awaiting contact"),IF(tblReferrals[[#This Row],[DaysToContact]]<0,"Check dates",IF(tblReferrals[[#This Row],[DaysToContact]]<=tblReferrals[[#This Row],[TargetDays]],"Contacted within target","Contacted late")))) | R7: =IF(tblReferrals[[#This Row],[PriorityLevel]]="","Missing priority",IF(tblReferrals[[#This Row],[ReferrerType]]="","Missing referrer type",IF(AND(tblReferrals[[#This Row],[DateFirstContact]]<>"",tblReferrals[[#This Row],[DaysToContact]]<0),"Contact before received",IF(AND(tblReferrals[[#This Row],[Status]]="Enrolled",tblReferrals[[#This Row],[ConsentObtained]]<>"Yes"),"Enrolled without consent",IF(COUNTIF(tblReferrals[ClientCode],tblReferrals[[#This Row],[ClientCode]])>1,"Possible duplicate client",IF(tblReferrals[[#This Row],[Ethnicity]]="","Ethnicity not recorded","OK"))))))
A8: R007 | B8: 46178 | C8: C1049 | D8: GP | F8: Routine | G8: Yes | H8: 46181 | I8: Phone | J8: Contacted | K8: Pending | M8: No | N8: =IF(tblReferrals[[#This Row],[DateFirstContact]]="","",tblReferrals[[#This Row],[DateFirstContact]]-tblReferrals[[#This Row],[DateReceived]]) | O8: =IF(tblReferrals[[#This Row],[DateFirstContact]]="",Settings!$B$3-tblReferrals[[#This Row],[DateReceived]],"") | P8: =IFERROR(INDEX(Settings!$B$6:$B$8,MATCH(tblReferrals[[#This Row],[PriorityLevel]],Settings!$A$6:$A$8,0)),"") | Q8: =IF(tblReferrals[[#This Row],[TargetDays]]="","Check priority",IF(tblReferrals[[#This Row],[DateFirstContact]]="",IF(tblReferrals[[#This Row],[DaysWaiting]]>tblReferrals[[#This Row],[TargetDays]],"Overdue - not contacted","Within target - awaiting contact"),IF(tblReferrals[[#This Row],[DaysToContact]]<0,"Check dates",IF(tblReferrals[[#This Row],[DaysToContact]]<=tblReferrals[[#This Row],[TargetDays]],"Contacted within target","Contacted late")))) | R8: =IF(tblReferrals[[#This Row],[PriorityLevel]]="","Missing priority",IF(tblReferrals[[#This Row],[ReferrerType]]="","Missing referrer type",IF(AND(tblReferrals[[#This Row],[DateFirstContact]]<>"",tblReferrals[[#This Row],[DaysToContact]]<0),"Contact before received",IF(AND(tblReferrals[[#This Row],[Status]]="Enrolled",tblReferrals[[#This Row],[ConsentObtained]]<>"Yes"),"Enrolled without consent",IF(COUNTIF(tblReferrals[ClientCode],tblReferrals[[#This Row],[ClientCode]])>1,"Possible duplicate client",IF(tblReferrals[[#This Row],[Ethnicity]]="","Ethnicity not recorded","OK"))))))
A9: R008 | B9: 46178 | C9: C1056 | D9: Other health provider | E9: European | F9: Routine | G9: Yes | H9: 46176 | I9: Text | J9: Declined | K9: No | M9: No | N9: =IF(tblReferrals[[#This Row],[DateFirstContact]]="","",tblReferrals[[#This Row],[DateFirstContact]]-tblReferrals[[#This Row],[DateReceived]]) | O9: =IF(tblReferrals[[#This Row],[DateFirstContact]]="",Settings!$B$3-tblReferrals[[#This Row],[DateReceived]],"") | P9: =IFERROR(INDEX(Settings!$B$6:$B$8,MATCH(tblReferrals[[#This Row],[PriorityLevel]],Settings!$A$6:$A$8,0)),"") | Q9: =IF(tblReferrals[[#This Row],[TargetDays]]="","Check priority",IF(tblReferrals[[#This Row],[DateFirstContact]]="",IF(tblReferrals[[#This Row],[DaysWaiting]]>tblReferrals[[#This Row],[TargetDays]],"Overdue - not contacted","Within target - awaiting contact"),IF(tblReferrals[[#This Row],[DaysToContact]]<0,"Check dates",IF(tblReferrals[[#This Row],[DaysToContact]]<=tblReferrals[[#This Row],[TargetDays]],"Contacted within target","Contacted late")))) | R9: =IF(tblReferrals[[#This Row],[PriorityLevel]]="","Missing priority",IF(tblReferrals[[#This Row],[ReferrerType]]="","Missing referrer type",IF(AND(tblReferrals[[#This Row],[DateFirstContact]]<>"",tblReferrals[[#This Row],[DaysToContact]]<0),"Contact before received",IF(AND(tblReferrals[[#This Row],[Status]]="Enrolled",tblReferrals[[#This Row],[ConsentObtained]]<>"Yes"),"Enrolled without consent",IF(COUNTIF(tblReferrals[ClientCode],tblReferrals[[#This Row],[ClientCode]])>1,"Possible duplicate client",IF(tblReferrals[[#This Row],[Ethnicity]]="","Ethnicity not recorded","OK"))))))
A10: R009 | B10: 46182 | C10: C1063 | D10: Hospital | E10: Asian | F10: High | G10: Yes | H10: 46185 | I10: Phone | J10: Declined | K10: No | M10: No | N10: =IF(tblReferrals[[#This Row],[DateFirstContact]]="","",tblReferrals[[#This Row],[DateFirstContact]]-tblReferrals[[#This Row],[DateReceived]]) | O10: =IF(tblReferrals[[#This Row],[DateFirstContact]]="",Settings!$B$3-tblReferrals[[#This Row],[DateReceived]],"") | P10: =IFERROR(INDEX(Settings!$B$6:$B$8,MATCH(tblReferrals[[#This Row],[PriorityLevel]],Settings!$A$6:$A$8,0)),"") | Q10: =IF(tblReferrals[[#This Row],[TargetDays]]="","Check priority",IF(tblReferrals[[#This Row],[DateFirstContact]]="",IF(tblReferrals[[#This Row],[DaysWaiting]]>tblReferrals[[#This Row],[TargetDays]],"Overdue - not contacted","Within target - awaiting contact"),IF(tblReferrals[[#This Row],[DaysToContact]]<0,"Check dates",IF(tblReferrals[[#This Row],[DaysToContact]]<=tblReferrals[[#This Row],[TargetDays]],"Contacted within target","Contacted late")))) | R10: =IF(tblReferrals[[#This Row],[PriorityLevel]]="","Missing priority",IF(tblReferrals[[#This Row],[ReferrerType]]="","Missing referrer type",IF(AND(tblReferrals[[#This Row],[DateFirstContact]]<>"",tblReferrals[[#This Row],[DaysToContact]]<0),"Contact before received",IF(AND(tblReferrals[[#This Row],[Status]]="Enrolled",tblReferrals[[#This Row],[ConsentObtained]]<>"Yes"),"Enrolled without consent",IF(COUNTIF(tblReferrals[ClientCode],tblReferrals[[#This Row],[ClientCode]])>1,"Possible duplicate client",IF(tblReferrals[[#This Row],[Ethnicity]]="","Ethnicity not recorded","OK"))))))
A11: R010 | B11: 46182 | C11: C1070 | D11: GP | E11: Other | F11: Routine | G11: Yes | H11: 46183 | I11: Phone | J11: Contacted | K11: Pending | L11: 46196 | M11: No | N11: =IF(tblReferrals[[#This Row],[DateFirstContact]]="","",tblReferrals[[#This Row],[DateFirstContact]]-tblReferrals[[#This Row],[DateReceived]]) | O11: =IF(tblReferrals[[#This Row],[DateFirstContact]]="",Settings!$B$3-tblReferrals[[#This Row],[DateReceived]],"") | P11: =IFERROR(INDEX(Settings!$B$6:$B$8,MATCH(tblReferrals[[#This Row],[PriorityLevel]],Settings!$A$6:$A$8,0)),"") | Q11: =IF(tblReferrals[[#This Row],[TargetDays]]="","Check priority",IF(tblReferrals[[#This Row],[DateFirstContact]]="",IF(tblReferrals[[#This Row],[DaysWaiting]]>tblReferrals[[#This Row],[TargetDays]],"Overdue - not contacted","Within target - awaiting contact"),IF(tblReferrals[[#This Row],[DaysToContact]]<0,"Check dates",IF(tblReferrals[[#This Row],[DaysToContact]]<=tblReferrals[[#This Row],[TargetDays]],"Contacted within target","Contacted late")))) | R11: =IF(tblReferrals[[#This Row],[PriorityLevel]]="","Missing priority",IF(tblReferrals[[#This Row],[ReferrerType]]="","Missing referrer type",IF(AND(tblReferrals[[#This Row],[DateFirstContact]]<>"",tblReferrals[[#This Row],[DaysToContact]]<0),"Contact before received",IF(AND(tblReferrals[[#This Row],[Status]]="Enrolled",tblReferrals[[#This Row],[ConsentObtained]]<>"Yes"),"Enrolled without consent",IF(COUNTIF(tblReferrals[ClientCode],tblReferrals[[#This Row],[ClientCode]])>1,"Possible duplicate client",IF(tblReferrals[[#This Row],[Ethnicity]]="","Ethnicity not recorded","OK"))))))
A12: R011 | B12: 46182 | C12: C1077 | D12: Self-referral | E12: European | G12: Yes | H12: 46189 | I12: Email | J12: Contacted | K12: Pending | M12: No | N12: =IF(tblReferrals[[#This Row],[DateFirstContact]]="","",tblReferrals[[#This Row],[DateFirstContact]]-tblReferrals[[#This Row],[DateReceived]]) | O12: =IF(tblReferrals[[#This Row],[DateFirstContact]]="",Settings!$B$3-tblReferrals[[#This Row],[DateReceived]],"") | P12: =IFERROR(INDEX(Settings!$B$6:$B$8,MATCH(tblReferrals[[#This Row],[PriorityLevel]],Settings!$A$6:$A$8,0)),"") | Q12: =IF(tblReferrals[[#This Row],[TargetDays]]="","Check priority",IF(tblReferrals[[#This Row],[DateFirstContact]]="",IF(tblReferrals[[#This Row],[DaysWaiting]]>tblReferrals[[#This Row],[TargetDays]],"Overdue - not contacted","Within target - awaiting contact"),IF(tblReferrals[[#This Row],[DaysToContact]]<0,"Check dates",IF(tblReferrals[[#This Row],[DaysToContact]]<=tblReferrals[[#This Row],[TargetDays]],"Contacted within target","Contacted late")))) | R12: =IF(tblReferrals[[#This Row],[PriorityLevel]]="","Missing priority",IF(tblReferrals[[#This Row],[ReferrerType]]="","Missing referrer type",IF(AND(tblReferrals[[#This Row],[DateFirstContact]]<>"",tblReferrals[[#This Row],[DaysToContact]]<0),"Contact before received",IF(AND(tblReferrals[[#This Row],[Status]]="Enrolled",tblReferrals[[#This Row],[ConsentObtained]]<>"Yes"),"Enrolled without consent",IF(COUNTIF(tblReferrals[ClientCode],tblReferrals[[#This Row],[ClientCode]])>1,"Possible duplicate client",IF(tblReferrals[[#This Row],[Ethnicity]]="","Ethnicity not recorded","OK"))))))
A13: R012 | B13: 46182 | C13: C1084 | D13: Community agency | E13: Asian | F13: Routine | G13: No | H13: 46195 | I13: In person | J13: Declined | K13: No | M13: No | N13: =IF(tblReferrals[[#This Row],[DateFirstContact]]="","",tblReferrals[[#This Row],[DateFirstContact]]-tblReferrals[[#This Row],[DateReceived]]) | O13: =IF(tblReferrals[[#This Row],[DateFirstContact]]="",Settings!$B$3-tblReferrals[[#This Row],[DateReceived]],"") | P13: =IFERROR(INDEX(Settings!$B$6:$B$8,MATCH(tblReferrals[[#This Row],[PriorityLevel]],Settings!$A$6:$A$8,0)),"") | Q13: =IF(tblReferrals[[#This Row],[TargetDays]]="","Check priority",IF(tblReferrals[[#This Row],[DateFirstContact]]="",IF(tblReferrals[[#This Row],[DaysWaiting]]>tblReferrals[[#This Row],[TargetDays]],"Overdue - not contacted","Within target - awaiting contact"),IF(tblReferrals[[#This Row],[DaysToContact]]<0,"Check dates",IF(tblReferrals[[#This Row],[DaysToContact]]<=tblReferrals[[#This Row],[TargetDays]],"Contacted within target","Contacted late")))) | R13: =IF(tblReferrals[[#This Row],[PriorityLevel]]="","Missing priority",IF(tblReferrals[[#This Row],[ReferrerType]]="","Missing referrer type",IF(AND(tblReferrals[[#This Row],[DateFirstContact]]<>"",tblReferrals[[#This Row],[DaysToContact]]<0),"Contact before received",IF(AND(tblReferrals[[#This Row],[Status]]="Enrolled",tblReferrals[[#This Row],[ConsentObtained]]<>"Yes"),"Enrolled without consent",IF(COUNTIF(tblReferrals[ClientCode],tblReferrals[[#This Row],[ClientCode]])>1,"Possible duplicate client",IF(tblReferrals[[#This Row],[Ethnicity]]="","Ethnicity not recorded","OK"))))))
A14: R013 | B14: 46183 | C14: C1091 | D14: GP | E14: European | F14: High | G14: No | H14: 46188 | I14: Phone | J14: Contacted | K14: Pending | L14: 46198 | M14: No | N14: =IF(tblReferrals[[#This Row],[DateFirstContact]]="","",tblReferrals[[#This Row],[DateFirstContact]]-tblReferrals[[#This Row],[DateReceived]]) | O14: =IF(tblReferrals[[#This Row],[DateFirstContact]]="",Settings!$B$3-tblReferrals[[#This Row],[DateReceived]],"") | P14: =IFERROR(INDEX(Settings!$B$6:$B$8,MATCH(tblReferrals[[#This Row],[PriorityLevel]],Settings!$A$6:$A$8,0)),"") | Q14: =IF(tblReferrals[[#This Row],[TargetDays]]="","Check priority",IF(tblReferrals[[#This Row],[DateFirstContact]]="",IF(tblReferrals[[#This Row],[DaysWaiting]]>tblReferrals[[#This Row],[TargetDays]],"Overdue - not contacted","Within target - awaiting contact"),IF(tblReferrals[[#This Row],[DaysToContact]]<0,"Check dates",IF(tblReferrals[[#This Row],[DaysToContact]]<=tblReferrals[[#This Row],[TargetDays]],"Contacted within target","Contacted late")))) | R14: =IF(tblReferrals[[#This Row],[PriorityLevel]]="","Missing priority",IF(tblReferrals[[#This Row],[ReferrerType]]="","Missing referrer type",IF(AND(tblReferrals[[#This Row],[DateFirstContact]]<>"",tblReferrals[[#This Row],[DaysToContact]]<0),"Contact before received",IF(AND(tblReferrals[[#This Row],[Status]]="Enrolled",tblReferrals[[#This Row],[ConsentObtained]]<>"Yes"),"Enrolled without consent",IF(COUNTIF(tblReferrals[ClientCode],tblReferrals[[#This Row],[ClientCode]])>1,"Possible duplicate client",IF(tblReferrals[[#This Row],[Ethnicity]]="","Ethnicity not recorded","OK"))))))
A15: R014 | B15: 46183 | C15: C1098 | D15: GP | E15: Asian | F15: Routine | G15: Yes | H15: 46185 | I15: Phone | J15: Consent pending | K15: Pending | M15: No | N15: =IF(tblReferrals[[#This Row],[DateFirstContact]]="","",tblReferrals[[#This Row],[DateFirstContact]]-tblReferrals[[#This Row],[DateReceived]]) | O15: =IF(tblReferrals[[#This Row],[DateFirstContact]]="",Settings!$B$3-tblReferrals[[#This Row],[DateReceived]],"") | P15: =IFERROR(INDEX(Settings!$B$6:$B$8,MATCH(tblReferrals[[#This Row],[PriorityLevel]],Settings!$A$6:$A$8,0)),"") | Q15: =IF(tblReferrals[[#This Row],[TargetDays]]="","Check priority",IF(tblReferrals[[#This Row],[DateFirstContact]]="",IF(tblReferrals[[#This Row],[DaysWaiting]]>tblReferrals[[#This Row],[TargetDays]],"Overdue - not contacted","Within target - awaiting contact"),IF(tblReferrals[[#This Row],[DaysToContact]]<0,"Check dates",IF(tblReferrals[[#This Row],[DaysToContact]]<=tblReferrals[[#This Row],[TargetDays]],"Contacted within target","Contacted late")))) | R15: =IF(tblReferrals[[#This Row],[PriorityLevel]]="","Missing priority",IF(tblReferrals[[#This Row],[ReferrerType]]="","Missing referrer type",IF(AND(tblReferrals[[#This Row],[DateFirstContact]]<>"",tblReferrals[[#This Row],[DaysToContact]]<0),"Contact before received",IF(AND(tblReferrals[[#This Row],[Status]]="Enrolled",tblReferrals[[#This Row],[ConsentObtained]]<>"Yes"),"Enrolled without consent",IF(COUNTIF(tblReferrals[ClientCode],tblReferrals[[#This Row],[ClientCode]])>1,"Possible duplicate client",IF(tblReferrals[[#This Row],[Ethnicity]]="","Ethnicity not recorded","OK"))))))
A16: R015 | B16: 46183 | C16: C1105 | D16: Midwife | E16: Asian | F16: Routine | G16: Yes | H16: 46189 | I16: Phone | J16: Enrolled | K16: Yes | L16: 46192 | M16: No | N16: =IF(tblReferrals[[#This Row],[DateFirstContact]]="","",tblReferrals[[#This Row],[DateFirstContact]]-tblReferrals[[#This Row],[DateReceived]]) | O16: =IF(tblReferrals[[#This Row],[DateFirstContact]]="",Settings!$B$3-tblReferrals[[#This Row],[DateReceived]],"") | P16: =IFERROR(INDEX(Settings!$B$6:$B$8,MATCH(tblReferrals[[#This Row],[PriorityLevel]],Settings!$A$6:$A$8,0)),"") | Q16: =IF(tblReferrals[[#This Row],[TargetDays]]="","Check priority",IF(tblReferrals[[#This Row],[DateFirstContact]]="",IF(tblReferrals[[#This Row],[DaysWaiting]]>tblReferrals[[#This Row],[TargetDays]],"Overdue - not contacted","Within target - awaiting contact"),IF(tblReferrals[[#This Row],[DaysToContact]]<0,"Check dates",IF(tblReferrals[[#This Row],[DaysToContact]]<=tblReferrals[[#This Row],[TargetDays]],"Contacted within target","Contacted late")))) | R16: =IF(tblReferrals[[#This Row],[PriorityLevel]]="","Missing priority",IF(tblReferrals[[#This Row],[ReferrerType]]="","Missing referrer type",IF(AND(tblReferrals[[#This Row],[DateFirstContact]]<>"",tblReferrals[[#This Row],[DaysToContact]]<0),"Contact before received",IF(AND(tblReferrals[[#This Row],[Status]]="Enrolled",tblReferrals[[#This Row],[ConsentObtained]]<>"Yes"),"Enrolled without consent",IF(COUNTIF(tblReferrals[ClientCode],tblReferrals[[#This Row],[ClientCode]])>1,"Possible duplicate client",IF(tblReferrals[[#This Row],[Ethnicity]]="","Ethnicity not recorded","OK"))))))
A17: R016 | B17: 46184 | C17: C1112 | D17: Self-referral | E17: Māori | F17: Routine | G17: No | H17: 46188 | I17: Email | J17: Consent pending | K17: Pending | M17: No | N17: =IF(tblReferrals[[#This Row],[DateFirstContact]]="","",tblReferrals[[#This Row],[DateFirstContact]]-tblReferrals[[#This Row],[DateReceived]]) | O17: =IF(tblReferrals[[#This Row],[DateFirstContact]]="",Settings!$B$3-tblReferrals[[#This Row],[DateReceived]],"") | P17: =IFERROR(INDEX(Settings!$B$6:$B$8,MATCH(tblReferrals[[#This Row],[PriorityLevel]],Settings!$A$6:$A$8,0)),"") | Q17: =IF(tblReferrals[[#This Row],[TargetDays]]="","Check priority",IF(tblReferrals[[#This Row],[DateFirstContact]]="",IF(tblReferrals[[#This Row],[DaysWaiting]]>tblReferrals[[#This Row],[TargetDays]],"Overdue - not contacted","Within target - awaiting contact"),IF(tblReferrals[[#This Row],[DaysToContact]]<0,"Check dates",IF(tblReferrals[[#This Row],[DaysToContact]]<=tblReferrals[[#This Row],[TargetDays]],"Contacted within target","Contacted late")))) | R17: =IF(tblReferrals[[#This Row],[PriorityLevel]]="","Missing priority",IF(tblReferrals[[#This Row],[ReferrerType]]="","Missing referrer type",IF(AND(tblReferrals[[#This Row],[DateFirstContact]]<>"",tblReferrals[[#This Row],[DaysToContact]]<0),"Contact before received",IF(AND(tblReferrals[[#This Row],[Status]]="Enrolled",tblReferrals[[#This Row],[ConsentObtained]]<>"Yes"),"Enrolled without consent",IF(COUNTIF(tblReferrals[ClientCode],tblReferrals[[#This Row],[ClientCode]])>1,"Possible duplicate client",IF(tblReferrals[[#This Row],[Ethnicity]]="","Ethnicity not recorded","OK"))))))
A18: R017 | B18: 46191 | C18: C1119 | D18: Midwife | E18: European | F18: Routine | G18: Yes | H18: 46198 | I18: Phone | J18: Declined | K18: No | M18: No | N18: =IF(tblReferrals[[#This Row],[DateFirstContact]]="","",tblReferrals[[#This Row],[DateFirstContact]]-tblReferrals[[#This Row],[DateReceived]]) | O18: =IF(tblReferrals[[#This Row],[DateFirstContact]]="",Settings!$B$3-tblReferrals[[#This Row],[DateReceived]],"") | P18: =IFERROR(INDEX(Settings!$B$6:$B$8,MATCH(tblReferrals[[#This Row],[PriorityLevel]],Settings!$A$6:$A$8,0)),"") | Q18: =IF(tblReferrals[[#This Row],[TargetDays]]="","Check priority",IF(tblReferrals[[#This Row],[DateFirstContact]]="",IF(tblReferrals[[#This Row],[DaysWaiting]]>tblReferrals[[#This Row],[TargetDays]],"Overdue - not contacted","Within target - awaiting contact"),IF(tblReferrals[[#This Row],[DaysToContact]]<0,"Check dates",IF(tblReferrals[[#This Row],[DaysToContact]]<=tblReferrals[[#This Row],[TargetDays]],"Contacted within target","Contacted late")))) | R18: =IF(tblReferrals[[#This Row],[PriorityLevel]]="","Missing priority",IF(tblReferrals[[#This Row],[ReferrerType]]="","Missing referrer type",IF(AND(tblReferrals[[#This Row],[DateFirstContact]]<>"",tblReferrals[[#This Row],[DaysToContact]]<0),"Contact before received",IF(AND(tblReferrals[[#This Row],[Status]]="Enrolled",tblReferrals[[#This Row],[ConsentObtained]]<>"Yes"),"Enrolled without consent",IF(COUNTIF(tblReferrals[ClientCode],tblReferrals[[#This Row],[ClientCode]])>1,"Possible duplicate client",IF(tblReferrals[[#This Row],[Ethnicity]]="","Ethnicity not recorded","OK"))))))
A19: R018 | B19: 46192 | C19: C1126 | D19: Midwife | E19: European | F19: High | G19: Yes | H19: 46199 | I19: Phone | J19: Declined | K19: No | M19: No | N19: =IF(tblReferrals[[#This Row],[DateFirstContact]]="","",tblReferrals[[#This Row],[DateFirstContact]]-tblReferrals[[#This Row],[DateReceived]]) | O19: =IF(tblReferrals[[#This Row],[DateFirstContact]]="",Settings!$B$3-tblReferrals[[#This Row],[DateReceived]],"") | P19: =IFERROR(INDEX(Settings!$B$6:$B$8,MATCH(tblReferrals[[#This Row],[PriorityLevel]],Settings!$A$6:$A$8,0)),"") | Q19: =IF(tblReferrals[[#This Row],[TargetDays]]="","Check priority",IF(tblReferrals[[#This Row],[DateFirstContact]]="",IF(tblReferrals[[#This Row],[DaysWaiting]]>tblReferrals[[#This Row],[TargetDays]],"Overdue - not contacted","Within target - awaiting contact"),IF(tblReferrals[[#This Row],[DaysToContact]]<0,"Check dates",IF(tblReferrals[[#This Row],[DaysToContact]]<=tblReferrals[[#This Row],[TargetDays]],"Contacted within target","Contacted late")))) | R19: =IF(tblReferrals[[#This Row],[PriorityLevel]]="","Missing priority",IF(tblReferrals[[#This Row],[ReferrerType]]="","Missing referrer type",IF(AND(tblReferrals[[#This Row],[DateFirstContact]]<>"",tblReferrals[[#This Row],[DaysToContact]]<0),"Contact before received",IF(AND(tblReferrals[[#This Row],[Status]]="Enrolled",tblReferrals[[#This Row],[ConsentObtained]]<>"Yes"),"Enrolled without consent",IF(COUNTIF(tblReferrals[ClientCode],tblReferrals[[#This Row],[ClientCode]])>1,"Possible duplicate client",IF(tblReferrals[[#This Row],[Ethnicity]]="","Ethnicity not recorded","OK"))))))
A20: R019 | B20: 46192 | C20: C1133 | D20: Hospital | E20: European | F20: High | G20: Yes | H20: 46196 | I20: Phone | J20: Enrolled | K20: Yes | L20: 46210 | M20: No | N20: =IF(tblReferrals[[#This Row],[DateFirstContact]]="","",tblReferrals[[#This Row],[DateFirstContact]]-tblReferrals[[#This Row],[DateReceived]]) | O20: =IF(tblReferrals[[#This Row],[DateFirstContact]]="",Settings!$B$3-tblReferrals[[#This Row],[DateReceived]],"") | P20: =IFERROR(INDEX(Settings!$B$6:$B$8,MATCH(tblReferrals[[#This Row],[PriorityLevel]],Settings!$A$6:$A$8,0)),"") | Q20: =IF(tblReferrals[[#This Row],[TargetDays]]="","Check priority",IF(tblReferrals[[#This Row],[DateFirstContact]]="",IF(tblReferrals[[#This Row],[DaysWaiting]]>tblReferrals[[#This Row],[TargetDays]],"Overdue - not contacted","Within target - awaiting contact"),IF(tblReferrals[[#This Row],[DaysToContact]]<0,"Check dates",IF(tblReferrals[[#This Row],[DaysToContact]]<=tblReferrals[[#This Row],[TargetDays]],"Contacted within target","Contacted late")))) | R20: =IF(tblReferrals[[#This Row],[PriorityLevel]]="","Missing priority",IF(tblReferrals[[#This Row],[ReferrerType]]="","Missing referrer type",IF(AND(tblReferrals[[#This Row],[DateFirstContact]]<>"",tblReferrals[[#This Row],[DaysToContact]]<0),"Contact before received",IF(AND(tblReferrals[[#This Row],[Status]]="Enrolled",tblReferrals[[#This Row],[ConsentObtained]]<>"Yes"),"Enrolled without consent",IF(COUNTIF(tblReferrals[ClientCode],tblReferrals[[#This Row],[ClientCode]])>1,"Possible duplicate client",IF(tblReferrals[[#This Row],[Ethnicity]]="","Ethnicity not recorded","OK"))))))
A21: R020 | B21: 46192 | C21: C1140 | D21: GP | E21: Māori | F21: High | G21: No | H21: 46195 | I21: Text | J21: Awaiting info | K21: Pending | M21: Yes | N21: =IF(tblReferrals[[#This Row],[DateFirstContact]]="","",tblReferrals[[#This Row],[DateFirstContact]]-tblReferrals[[#This Row],[DateReceived]]) | O21: =IF(tblReferrals[[#This Row],[DateFirstContact]]="",Settings!$B$3-tblReferrals[[#This Row],[DateReceived]],"") | P21: =IFERROR(INDEX(Settings!$B$6:$B$8,MATCH(tblReferrals[[#This Row],[PriorityLevel]],Settings!$A$6:$A$8,0)),"") | Q21: =IF(tblReferrals[[#This Row],[TargetDays]]="","Check priority",IF(tblReferrals[[#This Row],[DateFirstContact]]="",IF(tblReferrals[[#This Row],[DaysWaiting]]>tblReferrals[[#This Row],[TargetDays]],"Overdue - not contacted","Within target - awaiting contact"),IF(tblReferrals[[#This Row],[DaysToContact]]<0,"Check dates",IF(tblReferrals[[#This Row],[DaysToContact]]<=tblReferrals[[#This Row],[TargetDays]],"Contacted within target","Contacted late")))) | R21: =IF(tblReferrals[[#This Row],[PriorityLevel]]="","Missing priority",IF(tblReferrals[[#This Row],[ReferrerType]]="","Missing referrer type",IF(AND(tblReferrals[[#This Row],[DateFirstContact]]<>"",tblReferrals[[#This Row],[DaysToContact]]<0),"Contact before received",IF(AND(tblReferrals[[#This Row],[Status]]="Enrolled",tblReferrals[[#This Row],[ConsentObtained]]<>"Yes"),"Enrolled without consent",IF(COUNTIF(tblReferrals[ClientCode],tblReferrals[[#This Row],[ClientCode]])>1,"Possible duplicate client",IF(tblReferrals[[#This Row],[Ethnicity]]="","Ethnicity not recorded","OK"))))))
A22: R021 | B22: 46195 | C22: C1147 | D22: Community agency | E22: Māori | F22: High | G22: Yes | H22: 46198 | I22: Text | J22: Consent pending | K22: Pending | M22: No | N22: =IF(tblReferrals[[#This Row],[DateFirstContact]]="","",tblReferrals[[#This Row],[DateFirstContact]]-tblReferrals[[#This Row],[DateReceived]]) | O22: =IF(tblReferrals[[#This Row],[DateFirstContact]]="",Settings!$B$3-tblReferrals[[#This Row],[DateReceived]],"") | P22: =IFERROR(INDEX(Settings!$B$6:$B$8,MATCH(tblReferrals[[#This Row],[PriorityLevel]],Settings!$A$6:$A$8,0)),"") | Q22: =IF(tblReferrals[[#This Row],[TargetDays]]="","Check priority",IF(tblReferrals[[#This Row],[DateFirstContact]]="",IF(tblReferrals[[#This Row],[DaysWaiting]]>tblReferrals[[#This Row],[TargetDays]],"Overdue - not contacted","Within target - awaiting contact"),IF(tblReferrals[[#This Row],[DaysToContact]]<0,"Check dates",IF(tblReferrals[[#This Row],[DaysToContact]]<=tblReferrals[[#This Row],[TargetDays]],"Contacted within target","Contacted late")))) | R22: =IF(tblReferrals[[#This Row],[PriorityLevel]]="","Missing priority",IF(tblReferrals[[#This Row],[ReferrerType]]="","Missing referrer type",IF(AND(tblReferrals[[#This Row],[DateFirstContact]]<>"",tblReferrals[[#This Row],[DaysToContact]]<0),"Contact before received",IF(AND(tblReferrals[[#This Row],[Status]]="Enrolled",tblReferrals[[#This Row],[ConsentObtained]]<>"Yes"),"Enrolled without consent",IF(COUNTIF(tblReferrals[ClientCode],tblReferrals[[#This Row],[ClientCode]])>1,"Possible duplicate client",IF(tblReferrals[[#This Row],[Ethnicity]]="","Ethnicity not recorded","OK"))))))
A23: R022 | B23: 46196 | C23: C1154 | D23: GP | E23: Pacific | F23: Routine | G23: Yes | H23: 46198 | I23: Phone | J23: Enrolled | K23: Yes | L23: 46210 | M23: No | N23: =IF(tblReferrals[[#This Row],[DateFirstContact]]="","",tblReferrals[[#This Row],[DateFirstContact]]-tblReferrals[[#This Row],[DateReceived]]) | O23: =IF(tblReferrals[[#This Row],[DateFirstContact]]="",Settings!$B$3-tblReferrals[[#This Row],[DateReceived]],"") | P23: =IFERROR(INDEX(Settings!$B$6:$B$8,MATCH(tblReferrals[[#This Row],[PriorityLevel]],Settings!$A$6:$A$8,0)),"") | Q23: =IF(tblReferrals[[#This Row],[TargetDays]]="","Check priority",IF(tblReferrals[[#This Row],[DateFirstContact]]="",IF(tblReferrals[[#This Row],[DaysWaiting]]>tblReferrals[[#This Row],[TargetDays]],"Overdue - not contacted","Within target - awaiting contact"),IF(tblReferrals[[#This Row],[DaysToContact]]<0,"Check dates",IF(tblReferrals[[#This Row],[DaysToContact]]<=tblReferrals[[#This Row],[TargetDays]],"Contacted within target","Contacted late")))) | R23: =IF(tblReferrals[[#This Row],[PriorityLevel]]="","Missing priority",IF(tblReferrals[[#This Row],[ReferrerType]]="","Missing referrer type",IF(AND(tblReferrals[[#This Row],[DateFirstContact]]<>"",tblReferrals[[#This Row],[DaysToContact]]<0),"Contact before received",IF(AND(tblReferrals[[#This Row],[Status]]="Enrolled",tblReferrals[[#This Row],[ConsentObtained]]<>"Yes"),"Enrolled without consent",IF(COUNTIF(tblReferrals[ClientCode],tblReferrals[[#This Row],[ClientCode]])>1,"Possible duplicate client",IF(tblReferrals[[#This Row],[Ethnicity]]="","Ethnicity not recorded","OK"))))))
A24: R023 | B24: 46196 | C24: C1161 | D24: Midwife | E24: Māori | F24: Urgent | G24: Yes | H24: 46197 | I24: Phone | J24: Enrolled | K24: Yes | L24: 46213 | M24: Yes | N24: =IF(tblReferrals[[#This Row],[DateFirstContact]]="","",tblReferrals[[#This Row],[DateFirstContact]]-tblReferrals[[#This Row],[DateReceived]]) | O24: =IF(tblReferrals[[#This Row],[DateFirstContact]]="",Settings!$B$3-tblReferrals[[#This Row],[DateReceived]],"") | P24: =IFERROR(INDEX(Settings!$B$6:$B$8,MATCH(tblReferrals[[#This Row],[PriorityLevel]],Settings!$A$6:$A$8,0)),"") | Q24: =IF(tblReferrals[[#This Row],[TargetDays]]="","Check priority",IF(tblReferrals[[#This Row],[DateFirstContact]]="",IF(tblReferrals[[#This Row],[DaysWaiting]]>tblReferrals[[#This Row],[TargetDays]],"Overdue - not contacted","Within target - awaiting contact"),IF(tblReferrals[[#This Row],[DaysToContact]]<0,"Check dates",IF(tblReferrals[[#This Row],[DaysToContact]]<=tblReferrals[[#This Row],[TargetDays]],"Contacted within target","Contacted late")))) | R24: =IF(tblReferrals[[#This Row],[PriorityLevel]]="","Missing priority",IF(tblReferrals[[#This Row],[ReferrerType]]="","Missing referrer type",IF(AND(tblReferrals[[#This Row],[DateFirstContact]]<>"",tblReferrals[[#This Row],[DaysToContact]]<0),"Contact before received",IF(AND(tblReferrals[[#This Row],[Status]]="Enrolled",tblReferrals[[#This Row],[ConsentObtained]]<>"Yes"),"Enrolled without consent",IF(COUNTIF(tblReferrals[ClientCode],tblReferrals[[#This Row],[ClientCode]])>1,"Possible duplicate client",IF(tblReferrals[[#This Row],[Ethnicity]]="","Ethnicity not recorded","OK"))))))
A25: R024 | B25: 46196 | C25: C1168 | D25: Hospital | E25: Other | F25: Urgent | G25: No | H25: 46198 | I25: In person | J25: Consent pending | K25: Pending | M25: Yes | N25: =IF(tblReferrals[[#This Row],[DateFirstContact]]="","",tblReferrals[[#This Row],[DateFirstContact]]-tblReferrals[[#This Row],[DateReceived]]) | O25: =IF(tblReferrals[[#This Row],[DateFirstContact]]="",Settings!$B$3-tblReferrals[[#This Row],[DateReceived]],"") | P25: =IFERROR(INDEX(Settings!$B$6:$B$8,MATCH(tblReferrals[[#This Row],[PriorityLevel]],Settings!$A$6:$A$8,0)),"") | Q25: =IF(tblReferrals[[#This Row],[TargetDays]]="","Check priority",IF(tblReferrals[[#This Row],[DateFirstContact]]="",IF(tblReferrals[[#This Row],[DaysWaiting]]>tblReferrals[[#This Row],[TargetDays]],"Overdue - not contacted","Within target - awaiting contact"),IF(tblReferrals[[#This Row],[DaysToContact]]<0,"Check dates",IF(tblReferrals[[#This Row],[DaysToContact]]<=tblReferrals[[#This Row],[TargetDays]],"Contacted within target","Contacted late")))) | R25: =IF(tblReferrals[[#This Row],[PriorityLevel]]="","Missing priority",IF(tblReferrals[[#This Row],[ReferrerType]]="","Missing referrer type",IF(AND(tblReferrals[[#This Row],[DateFirstContact]]<>"",tblReferrals[[#This Row],[DaysToContact]]<0),"Contact before received",IF(AND(tblReferrals[[#This Row],[Status]]="Enrolled",tblReferrals[[#This Row],[ConsentObtained]]<>"Yes"),"Enrolled without consent",IF(COUNTIF(tblReferrals[ClientCode],tblReferrals[[#This Row],[ClientCode]])>1,"Possible duplicate client",IF(tblReferrals[[#This Row],[Ethnicity]]="","Ethnicity not recorded","OK"))))))
A26: R025 | B26: 46197 | C26: C1175 | D26: Other health provider | E26: Pacific | F26: High | G26: Yes | H26: 46197 | I26: Phone | J26: Enrolled | K26: Yes | L26: 46206 | M26: No | N26: =IF(tblReferrals[[#This Row],[DateFirstContact]]="","",tblReferrals[[#This Row],[DateFirstContact]]-tblReferrals[[#This Row],[DateReceived]]) | O26: =IF(tblReferrals[[#This Row],[DateFirstContact]]="",Settings!$B$3-tblReferrals[[#This Row],[DateReceived]],"") | P26: =IFERROR(INDEX(Settings!$B$6:$B$8,MATCH(tblReferrals[[#This Row],[PriorityLevel]],Settings!$A$6:$A$8,0)),"") | Q26: =IF(tblReferrals[[#This Row],[TargetDays]]="","Check priority",IF(tblReferrals[[#This Row],[DateFirstContact]]="",IF(tblReferrals[[#This Row],[DaysWaiting]]>tblReferrals[[#This Row],[TargetDays]],"Overdue - not contacted","Within target - awaiting contact"),IF(tblReferrals[[#This Row],[DaysToContact]]<0,"Check dates",IF(tblReferrals[[#This Row],[DaysToContact]]<=tblReferrals[[#This Row],[TargetDays]],"Contacted within target","Contacted late")))) | R26: =IF(tblReferrals[[#This Row],[PriorityLevel]]="","Missing priority",IF(tblReferrals[[#This Row],[ReferrerType]]="","Missing referrer type",IF(AND(tblReferrals[[#This Row],[DateFirstContact]]<>"",tblReferrals[[#This Row],[DaysToContact]]<0),"Contact before received",IF(AND(tblReferrals[[#This Row],[Status]]="Enrolled",tblReferrals[[#This Row],[ConsentObtained]]<>"Yes"),"Enrolled without consent",IF(COUNTIF(tblReferrals[ClientCode],tblReferrals[[#This Row],[ClientCode]])>1,"Possible duplicate client",IF(tblReferrals[[#This Row],[Ethnicity]]="","Ethnicity not recorded","OK"))))))
A27: R026 | B27: 46197 | C27: C1182 | D27: Hospital | E27: European | F27: Routine | G27: Yes | H27: 46199 | I27: Phone | J27: Consent pending | K27: Pending | M27: No | N27: =IF(tblReferrals[[#This Row],[DateFirstContact]]="","",tblReferrals[[#This Row],[DateFirstContact]]-tblReferrals[[#This Row],[DateReceived]]) | O27: =IF(tblReferrals[[#This Row],[DateFirstContact]]="",Settings!$B$3-tblReferrals[[#This Row],[DateReceived]],"") | P27: =IFERROR(INDEX(Settings!$B$6:$B$8,MATCH(tblReferrals[[#This Row],[PriorityLevel]],Settings!$A$6:$A$8,0)),"") | Q27: =IF(tblReferrals[[#This Row],[TargetDays]]="","Check priority",IF(tblReferrals[[#This Row],[DateFirstContact]]="",IF(tblReferrals[[#This Row],[DaysWaiting]]>tblReferrals[[#This Row],[TargetDays]],"Overdue - not contacted","Within target - awaiting contact"),IF(tblReferrals[[#This Row],[DaysToContact]]<0,"Check dates",IF(tblReferrals[[#This Row],[DaysToContact]]<=tblReferrals[[#This Row],[TargetDays]],"Contacted within target","Contacted late")))) | R27: =IF(tblReferrals[[#This Row],[PriorityLevel]]="","Missing priority",IF(tblReferrals[[#This Row],[ReferrerType]]="","Missing referrer type",IF(AND(tblReferrals[[#This Row],[DateFirstContact]]<>"",tblReferrals[[#This Row],[DaysToContact]]<0),"Contact before received",IF(AND(tblReferrals[[#This Row],[Status]]="Enrolled",tblReferrals[[#This Row],[ConsentObtained]]<>"Yes"),"Enrolled without consent",IF(COUNTIF(tblReferrals[ClientCode],tblReferrals[[#This Row],[ClientCode]])>1,"Possible duplicate client",IF(tblReferrals[[#This Row],[Ethnicity]]="","Ethnicity not recorded","OK"))))))
A28: R027 | B28: 46198 | C28: C1189 | D28: GP | E28: European | F28: Routine | G28: No | H28: 46204 | I28: Phone | J28: Awaiting info | K28: Pending | M28: No | N28: =IF(tblReferrals[[#This Row],[DateFirstContact]]="","",tblReferrals[[#This Row],[DateFirstContact]]-tblReferrals[[#This Row],[DateReceived]]) | O28: =IF(tblReferrals[[#This Row],[DateFirstContact]]="",Settings!$B$3-tblReferrals[[#This Row],[DateReceived]],"") | P28: =IFERROR(INDEX(Settings!$B$6:$B$8,MATCH(tblReferrals[[#This Row],[PriorityLevel]],Settings!$A$6:$A$8,0)),"") | Q28: =IF(tblReferrals[[#This Row],[TargetDays]]="","Check priority",IF(tblReferrals[[#This Row],[DateFirstContact]]="",IF(tblReferrals[[#This Row],[DaysWaiting]]>tblReferrals[[#This Row],[TargetDays]],"Overdue - not contacted","Within target - awaiting contact"),IF(tblReferrals[[#This Row],[DaysToContact]]<0,"Check dates",IF(tblReferrals[[#This Row],[DaysToContact]]<=tblReferrals[[#This Row],[TargetDays]],"Contacted within target","Contacted late")))) | R28: =IF(tblReferrals[[#This Row],[PriorityLevel]]="","Missing priority",IF(tblReferrals[[#This Row],[ReferrerType]]="","Missing referrer type",IF(AND(tblReferrals[[#This Row],[DateFirstContact]]<>"",tblReferrals[[#This Row],[DaysToContact]]<0),"Contact before received",IF(AND(tblReferrals[[#This Row],[Status]]="Enrolled",tblReferrals[[#This Row],[ConsentObtained]]<>"Yes"),"Enrolled without consent",IF(COUNTIF(tblReferrals[ClientCode],tblReferrals[[#This Row],[ClientCode]])>1,"Possible duplicate client",IF(tblReferrals[[#This Row],[Ethnicity]]="","Ethnicity not recorded","OK"))))))
A29: R028 | B29: 46199 | C29: C1196 | D29: GP | E29: Asian | F29: High | G29: Yes | H29: 46202 | I29: In person | J29: Enrolled | K29: Yes | L29: 46216 | M29: No | N29: =IF(tblReferrals[[#This Row],[DateFirstContact]]="","",tblReferrals[[#This Row],[DateFirstContact]]-tblReferrals[[#This Row],[DateReceived]]) | O29: =IF(tblReferrals[[#This Row],[DateFirstContact]]="",Settings!$B$3-tblReferrals[[#This Row],[DateReceived]],"") | P29: =IFERROR(INDEX(Settings!$B$6:$B$8,MATCH(tblReferrals[[#This Row],[PriorityLevel]],Settings!$A$6:$A$8,0)),"") | Q29: =IF(tblReferrals[[#This Row],[TargetDays]]="","Check priority",IF(tblReferrals[[#This Row],[DateFirstContact]]="",IF(tblReferrals[[#This Row],[DaysWaiting]]>tblReferrals[[#This Row],[TargetDays]],"Overdue - not contacted","Within target - awaiting contact"),IF(tblReferrals[[#This Row],[DaysToContact]]<0,"Check dates",IF(tblReferrals[[#This Row],[DaysToContact]]<=tblReferrals[[#This Row],[TargetDays]],"Contacted within target","Contacted late")))) | R29: =IF(tblReferrals[[#This Row],[PriorityLevel]]="","Missing priority",IF(tblReferrals[[#This Row],[ReferrerType]]="","Missing referrer type",IF(AND(tblReferrals[[#This Row],[DateFirstContact]]<>"",tblReferrals[[#This Row],[DaysToContact]]<0),"Contact before received",IF(AND(tblReferrals[[#This Row],[Status]]="Enrolled",tblReferrals[[#This Row],[ConsentObtained]]<>"Yes"),"Enrolled without consent",IF(COUNTIF(tblReferrals[ClientCode],tblReferrals[[#This Row],[ClientCode]])>1,"Possible duplicate client",IF(tblReferrals[[#This Row],[Ethnicity]]="","Ethnicity not recorded","OK"))))))
A30: R029 | B30: 46199 | C30: C1203 | D30: Hospital | E30: European | F30: Urgent | G30: Yes | H30: 46199 | I30: Phone | J30: Enrolled | K30: Yes | L30: 46217 | M30: Yes | N30: =IF(tblReferrals[[#This Row],[DateFirstContact]]="","",tblReferrals[[#This Row],[DateFirstContact]]-tblReferrals[[#This Row],[DateReceived]]) | O30: =IF(tblReferrals[[#This Row],[DateFirstContact]]="",Settings!$B$3-tblReferrals[[#This Row],[DateReceived]],"") | P30: =IFERROR(INDEX(Settings!$B$6:$B$8,MATCH(tblReferrals[[#This Row],[PriorityLevel]],Settings!$A$6:$A$8,0)),"") | Q30: =IF(tblReferrals[[#This Row],[TargetDays]]="","Check priority",IF(tblReferrals[[#This Row],[DateFirstContact]]="",IF(tblReferrals[[#This Row],[DaysWaiting]]>tblReferrals[[#This Row],[TargetDays]],"Overdue - not contacted","Within target - awaiting contact"),IF(tblReferrals[[#This Row],[DaysToContact]]<0,"Check dates",IF(tblReferrals[[#This Row],[DaysToContact]]<=tblReferrals[[#This Row],[TargetDays]],"Contacted within target","Contacted late")))) | R30: =IF(tblReferrals[[#This Row],[PriorityLevel]]="","Missing priority",IF(tblReferrals[[#This Row],[ReferrerType]]="","Missing referrer type",IF(AND(tblReferrals[[#This Row],[DateFirstContact]]<>"",tblReferrals[[#This Row],[DaysToContact]]<0),"Contact before received",IF(AND(tblReferrals[[#This Row],[Status]]="Enrolled",tblReferrals[[#This Row],[ConsentObtained]]<>"Yes"),"Enrolled without consent",IF(COUNTIF(tblReferrals[ClientCode],tblReferrals[[#This Row],[ClientCode]])>1,"Possible duplicate client",IF(tblReferrals[[#This Row],[Ethnicity]]="","Ethnicity not recorded","OK"))))))
A31: R030 | B31: 46202 | C31: C1210 | D31: Midwife | E31: European | F31: Routine | G31: No | H31: 46213 | I31: Phone | J31: Awaiting info | K31: Pending | M31: No | N31: =IF(tblReferrals[[#This Row],[DateFirstContact]]="","",tblReferrals[[#This Row],[DateFirstContact]]-tblReferrals[[#This Row],[DateReceived]]) | O31: =IF(tblReferrals[[#This Row],[DateFirstContact]]="",Settings!$B$3-tblReferrals[[#This Row],[DateReceived]],"") | P31: =IFERROR(INDEX(Settings!$B$6:$B$8,MATCH(tblReferrals[[#This Row],[PriorityLevel]],Settings!$A$6:$A$8,0)),"") | Q31: =IF(tblReferrals[[#This Row],[TargetDays]]="","Check priority",IF(tblReferrals[[#This Row],[DateFirstContact]]="",IF(tblReferrals[[#This Row],[DaysWaiting]]>tblReferrals[[#This Row],[TargetDays]],"Overdue - not contacted","Within target - awaiting contact"),IF(tblReferrals[[#This Row],[DaysToContact]]<0,"Check dates",IF(tblReferrals[[#This Row],[DaysToContact]]<=tblReferrals[[#This Row],[TargetDays]],"Contacted within target","Contacted late")))) | R31: =IF(tblReferrals[[#This Row],[PriorityLevel]]="","Missing priority",IF(tblReferrals[[#This Row],[ReferrerType]]="","Missing referrer type",IF(AND(tblReferrals[[#This Row],[DateFirstContact]]<>"",tblReferrals[[#This Row],[DaysToContact]]<0),"Contact before received",IF(AND(tblReferrals[[#This Row],[Status]]="Enrolled",tblReferrals[[#This Row],[ConsentObtained]]<>"Yes"),"Enrolled without consent",IF(COUNTIF(tblReferrals[ClientCode],tblReferrals[[#This Row],[ClientCode]])>1,"Possible duplicate client",IF(tblReferrals[[#This Row],[Ethnicity]]="","Ethnicity not recorded","OK"))))))
A32: R031 | B32: 46204 | C32: C1217 | D32: Midwife | E32: Pacific | F32: High | G32: Yes | H32: 46205 | I32: Email | J32: Enrolled | K32: Yes | L32: 46220 | M32: No | N32: =IF(tblReferrals[[#This Row],[DateFirstContact]]="","",tblReferrals[[#This Row],[DateFirstContact]]-tblReferrals[[#This Row],[DateReceived]]) | O32: =IF(tblReferrals[[#This Row],[DateFirstContact]]="",Settings!$B$3-tblReferrals[[#This Row],[DateReceived]],"") | P32: =IFERROR(INDEX(Settings!$B$6:$B$8,MATCH(tblReferrals[[#This Row],[PriorityLevel]],Settings!$A$6:$A$8,0)),"") | Q32: =IF(tblReferrals[[#This Row],[TargetDays]]="","Check priority",IF(tblReferrals[[#This Row],[DateFirstContact]]="",IF(tblReferrals[[#This Row],[DaysWaiting]]>tblReferrals[[#This Row],[TargetDays]],"Overdue - not contacted","Within target - awaiting contact"),IF(tblReferrals[[#This Row],[DaysToContact]]<0,"Check dates",IF(tblReferrals[[#This Row],[DaysToContact]]<=tblReferrals[[#This Row],[TargetDays]],"Contacted within target","Contacted late")))) | R32: =IF(tblReferrals[[#This Row],[PriorityLevel]]="","Missing priority",IF(tblReferrals[[#This Row],[ReferrerType]]="","Missing referrer type",IF(AND(tblReferrals[[#This Row],[DateFirstContact]]<>"",tblReferrals[[#This Row],[DaysToContact]]<0),"Contact before received",IF(AND(tblReferrals[[#This Row],[Status]]="Enrolled",tblReferrals[[#This Row],[ConsentObtained]]<>"Yes"),"Enrolled without consent",IF(COUNTIF(tblReferrals[ClientCode],tblReferrals[[#This Row],[ClientCode]])>1,"Possible duplicate client",IF(tblReferrals[[#This Row],[Ethnicity]]="","Ethnicity not recorded","OK"))))))
A33: R032 | B33: 46205 | C33: C1224 | D33: GP | E33: Māori | F33: Routine | G33: Yes | H33: 46209 | I33: Phone | J33: Enrolled | K33: Yes | L33: 46225 | M33: No | N33: =IF(tblReferrals[[#This Row],[DateFirstContact]]="","",tblReferrals[[#This Row],[DateFirstContact]]-tblReferrals[[#This Row],[DateReceived]]) | O33: =IF(tblReferrals[[#This Row],[DateFirstContact]]="",Settings!$B$3-tblReferrals[[#This Row],[DateReceived]],"") | P33: =IFERROR(INDEX(Settings!$B$6:$B$8,MATCH(tblReferrals[[#This Row],[PriorityLevel]],Settings!$A$6:$A$8,0)),"") | Q33: =IF(tblReferrals[[#This Row],[TargetDays]]="","Check priority",IF(tblReferrals[[#This Row],[DateFirstContact]]="",IF(tblReferrals[[#This Row],[DaysWaiting]]>tblReferrals[[#This Row],[TargetDays]],"Overdue - not contacted","Within target - awaiting contact"),IF(tblReferrals[[#This Row],[DaysToContact]]<0,"Check dates",IF(tblReferrals[[#This Row],[DaysToContact]]<=tblReferrals[[#This Row],[TargetDays]],"Contacted within target","Contacted late")))) | R33: =IF(tblReferrals[[#This Row],[PriorityLevel]]="","Missing priority",IF(tblReferrals[[#This Row],[ReferrerType]]="","Missing referrer type",IF(AND(tblReferrals[[#This Row],[DateFirstContact]]<>"",tblReferrals[[#This Row],[DaysToContact]]<0),"Contact before received",IF(AND(tblReferrals[[#This Row],[Status]]="Enrolled",tblReferrals[[#This Row],[ConsentObtained]]<>"Yes"),"Enrolled without consent",IF(COUNTIF(tblReferrals[ClientCode],tblReferrals[[#This Row],[ClientCode]])>1,"Possible duplicate client",IF(tblReferrals[[#This Row],[Ethnicity]]="","Ethnicity not recorded","OK"))))))
A34: R033 | B34: 46209 | C34: C1231 | D34: Community agency | E34: Māori | F34: Routine | G34: Yes | H34: 46212 | I34: Phone | J34: Enrolled | K34: Yes | L34: 46225 | M34: Yes | N34: =IF(tblReferrals[[#This Row],[DateFirstContact]]="","",tblReferrals[[#This Row],[DateFirstContact]]-tblReferrals[[#This Row],[DateReceived]]) | O34: =IF(tblReferrals[[#This Row],[DateFirstContact]]="",Settings!$B$3-tblReferrals[[#This Row],[DateReceived]],"") | P34: =IFERROR(INDEX(Settings!$B$6:$B$8,MATCH(tblReferrals[[#This Row],[PriorityLevel]],Settings!$A$6:$A$8,0)),"") | Q34: =IF(tblReferrals[[#This Row],[TargetDays]]="","Check priority",IF(tblReferrals[[#This Row],[DateFirstContact]]="",IF(tblReferrals[[#This Row],[DaysWaiting]]>tblReferrals[[#This Row],[TargetDays]],"Overdue - not contacted","Within target - awaiting contact"),IF(tblReferrals[[#This Row],[DaysToContact]]<0,"Check dates",IF(tblReferrals[[#This Row],[DaysToContact]]<=tblReferrals[[#This Row],[TargetDays]],"Contacted within target","Contacted late")))) | R34: =IF(tblReferrals[[#This Row],[PriorityLevel]]="","Missing priority",IF(tblReferrals[[#This Row],[ReferrerType]]="","Missing referrer type",IF(AND(tblReferrals[[#This Row],[DateFirstContact]]<>"",tblReferrals[[#This Row],[DaysToContact]]<0),"Contact before received",IF(AND(tblReferrals[[#This Row],[Status]]="Enrolled",tblReferrals[[#This Row],[ConsentObtained]]<>"Yes"),"Enrolled without consent",IF(COUNTIF(tblReferrals[ClientCode],tblReferrals[[#This Row],[ClientCode]])>1,"Possible duplicate client",IF(tblReferrals[[#This Row],[Ethnicity]]="","Ethnicity not recorded","OK"))))))
A35: R034 | B35: 46210 | C35: C1238 | D35: GP | E35: European | F35: Routine | G35: Yes | H35: 46216 | I35: Text | J35: Enrolled | K35: Yes | L35: 46227 | M35: No | N35: =IF(tblReferrals[[#This Row],[DateFirstContact]]="","",tblReferrals[[#This Row],[DateFirstContact]]-tblReferrals[[#This Row],[DateReceived]]) | O35: =IF(tblReferrals[[#This Row],[DateFirstContact]]="",Settings!$B$3-tblReferrals[[#This Row],[DateReceived]],"") | P35: =IFERROR(INDEX(Settings!$B$6:$B$8,MATCH(tblReferrals[[#This Row],[PriorityLevel]],Settings!$A$6:$A$8,0)),"") | Q35: =IF(tblReferrals[[#This Row],[TargetDays]]="","Check priority",IF(tblReferrals[[#This Row],[DateFirstContact]]="",IF(tblReferrals[[#This Row],[DaysWaiting]]>tblReferrals[[#This Row],[TargetDays]],"Overdue - not contacted","Within target - awaiting contact"),IF(tblReferrals[[#This Row],[DaysToContact]]<0,"Check dates",IF(tblReferrals[[#This Row],[DaysToContact]]<=tblReferrals[[#This Row],[TargetDays]],"Contacted within target","Contacted late")))) | R35: =IF(tblReferrals[[#This Row],[PriorityLevel]]="","Missing priority",IF(tblReferrals[[#This Row],[ReferrerType]]="","Missing referrer type",IF(AND(tblReferrals[[#This Row],[DateFirstContact]]<>"",tblReferrals[[#This Row],[DaysToContact]]<0),"Contact before received",IF(AND(tblReferrals[[#This Row],[Status]]="Enrolled",tblReferrals[[#This Row],[ConsentObtained]]<>"Yes"),"Enrolled without consent",IF(COUNTIF(tblReferrals[ClientCode],tblReferrals[[#This Row],[ClientCode]])>1,"Possible duplicate client",IF(tblReferrals[[#This Row],[Ethnicity]]="","Ethnicity not recorded","OK"))))))
A36: R035 | B36: 46211 | C36: C1014 | D36: Midwife | E36: European | F36: High | G36: Yes | H36: 46219 | I36: Email | J36: Unable to contact | K36: Pending | M36: No | N36: =IF(tblReferrals[[#This Row],[DateFirstContact]]="","",tblReferrals[[#This Row],[DateFirstContact]]-tblReferrals[[#This Row],[DateReceived]]) | O36: =IF(tblReferrals[[#This Row],[DateFirstContact]]="",Settings!$B$3-tblReferrals[[#This Row],[DateReceived]],"") | P36: =IFERROR(INDEX(Settings!$B$6:$B$8,MATCH(tblReferrals[[#This Row],[PriorityLevel]],Settings!$A$6:$A$8,0)),"") | Q36: =IF(tblReferrals[[#This Row],[TargetDays]]="","Check priority",IF(tblReferrals[[#This Row],[DateFirstContact]]="",IF(tblReferrals[[#This Row],[DaysWaiting]]>tblReferrals[[#This Row],[TargetDays]],"Overdue - not contacted","Within target - awaiting contact"),IF(tblReferrals[[#This Row],[DaysToContact]]<0,"Check dates",IF(tblReferrals[[#This Row],[DaysToContact]]<=tblReferrals[[#This Row],[TargetDays]],"Contacted within target","Contacted late")))) | R36: =IF(tblReferrals[[#This Row],[PriorityLevel]]="","Missing priority",IF(tblReferrals[[#This Row],[ReferrerType]]="","Missing referrer type",IF(AND(tblReferrals[[#This Row],[DateFirstContact]]<>"",tblReferrals[[#This Row],[DaysToContact]]<0),"Contact before received",IF(AND(tblReferrals[[#This Row],[Status]]="Enrolled",tblReferrals[[#This Row],[ConsentObtained]]<>"Yes"),"Enrolled without consent",IF(COUNTIF(tblReferrals[ClientCode],tblReferrals[[#This Row],[ClientCode]])>1,"Possible duplicate client",IF(tblReferrals[[#This Row],[Ethnicity]]="","Ethnicity not recorded","OK"))))))
